Workbook
Name Slicer_Measure: #N/A
Name Slicer_Measure2: #N/A
Name Slicer_Org_name: #N/A
Name Slicer_Organisation_name: #N/A
Name Slicer_Organisation_name1: #N/A
Name Slicer_Region: #N/A
Name Slicer_Region1: #N/A
Name Slicer_Staff_Group: #N/A
Name Slicer_Staff_Group2: #N/A

Sheet Introduction
B1: Experimental Statistics
B5: Supplementary Data Quality Review and Exploratory Analysis of HES A&E Activity and Reported Workforce Statistics
B6: Hospital Episode Statistics (HES) & NHS Hospital & Community Health Service (HCHS) workforce statistics
B7: Interactive Provider Analysis
B8: Publication Date: 13th September 2018
B10: This following supplementary analysis classified as experimental statistics is part of the wider Hospital Accident and Emergency Activity 2017-18 statistical release. It seeks to assist users of the data in understanding the data quality of reported time spent within A&E within HES data by enabling through an interactive visualisation the distribution of reported HES A&E data against calculated national and provider level figures. It also enables such distributions to be viewed at specific NHS Commissioning Region level to be selected to understand potential regional variations in reported activity. Additional exploratory analysis is also presented using HCHS workforce data held within NHS Digital to explore how workforce data held within NHS Digital maybe used to support future data reporting requirements and presenting results of preliminary investigations exploring relationships between A&E activity and staffing. Data is presented so as to enable A&E activity alongside corresponding workforce data relating specifically to staff employed within an A&E setting to be reviewed at specific provider/s level. Please note this analysis and its associated results are neither intended or suitable for any performance monitoring use. The A&E Attendances and Emergency Admissions Monthly Situation Reports (MSitAE) data collected by NHSE are the Official Data source which are used for such purposes. HES A&E data has been used in the additional exploratory analysis in preference to the MSitAE because of its greater scope to investigate other potential variables that may be of interest in the future such as patient age and Casemix. Hospital A&E activity is included as part of the Hospital Accident and Emergency Statistics reports. Workforce data is extracted from NHS's HR and Payroll system. Links to these statistics are available here:
B11: https://digital.nhs.uk/data-and-information/publications/statistical/hospital-accident--emergency-activity
B12: https://digital.nhs.uk/data-and-information/publications/statistical/nhs-workforce-statistics
B13: Experimental statistics are official statistics which are published in order to involve users and stakeholders in their development and as a means to build in quality at an early stage. It is important that users understand that limitations may apply to the interpretation of this data. More details are given in the footnotes tab within this document. Find out more about Experimental Statistics at https://gss.civilservice.gov.uk/wp-content/uploads/2016/02/Guidance-on- Experimental-Statistics_1.0.pdf
B15: To use this file: Select the measure and staff group you wish to view from the selection box at the top of the 'National' sheet; Select the provider you wish to view from the selection box at the top of the 'Provider' sheet; the graph/data will automatically update to show information relating to your selection. The 'Footnotes' page contains definitions for the text used.
B16: Feedback on the content, functionality and layout of this report is welcome. Feedback can be sent to enquiries@nhsdigital.nhs.uk, quoting ‘Accident and Emergency Statistics' in the subject title.
B17: Underlying data are contained on hidden sheets in this workbook. In order to assure functionality these sheets are password-protected but the underlying data are made available as a machine readable file on the publication page for this release.
... B37: or email: psi@nationalarchives.gsi.gov.uk

Sheet Notes and Definitions
B1: Experimental Statistics
B8: Supplementary Data Quality Review and Exploratory Analysis of HES A&E Activity and Reported Workforce Statistics
B9: Hospital Episode Statistics (HES) & NHS Hospital & Community Health Service (HCHS) workforce statistics
B11: Please note this analysis and its associated results are neither intended or suitable for any performance monitoring use. The A&E Attendances and Emergency Admissions Monthly Situation Reports (MSitAE) data collected by NHSE are the Official Data source which are used for such purposes.
B13: Notes and Definitions
B15: This supplmentary analysis undertaken by NHS Digital seeks to assist users of the data in understanding the data quality of reported time spent within A&E within HES data by enabling through an interactive visualisation the distribution of reported HES A&E data against calculated national and provider level figures. Additional exploratory analysis is also presented using HCHS workforce data limited to staff directly recorded as being employed within an A&E setting held within NHS Digital to explore how workforce data held within NHS Digital maybe used to support future data reporting requirements and presenting results of preliminary investigations exploring relationships between A&E activity and staffing . A small number of experimental measures have been used within this analysis the description and details of which are listed below. These statistics have been published in order to involve users and stakeholders in their development and as a means to build in quality at an early stage and we welcome feedback on their construction via email sent to enquiries@nhsdigital.nhs.uk, quoting ‘Accident and Emergency Statistics' in the subject title.
B16: Please note that the footnotes displayed here are not extensive and do not include information relating to data quality or data collection processes. For a complete set of data quality information, this can be accessed via: HES Data Quality https://digital.nhs.uk/data-and-information/data-tools-and-services/data-services/hospital-episode-statistics/the-processing-cycle-and-hes-data-quality HCHS Data Quality https://files.digital.nhs.uk/EF/316A87/NHS%20Workforce%20Statistics%2C%20March%202018%20Bulletin.pdf
B17: This report uses activity that was submitted for the reporting period of April 2017 to March 2018.
B18: This report only includes providers that are present in both the HES A&E activity data and NHS Digitals HCHS Workforce publication reports (for organisations reporting staff employed specifically in an A&E setting).
B20: Terminology and Definitions
B21: Workforce data used within this analysis has been restricted to only count staff reported as being employed within an A&E setting within HCHS data. The following descriptions therefore relate solely to this pre defined cohort. Staff Group - These are aggregate grouping of people performing specific workforce roles within the English NHS used in HCHS Workforce Data published by NHS Digital: The following Staffing Groups have been used in this analyses: Doctor: (Stability Index only) All HCHS Doctors this includes Consultants Consultant: (Staff per attendance only) These are Consultant Doctors (including directors of Public Health) Doctor (excl. Consultant): (Staff per attendance only) All HCHS Doctors, excluding Consultant Doctors Nurses: All nurses and health visitors Care Providers (excl. Doctors and Nurses): Ambulance staff; scientific, therapeutic & technical staff; support to doctors, nurses and midwives; support to ambulance staff; support to ST&T staff Please note that the following Staff Groups have been excluded from this analysis: General functions; Hotel, property & estates; Senior managers; Managers; Other staff or those with unknown classification Additionally there are staff that work in providers that are excluded from this analysis, due to not being collected within the Workforce publication. Such as physiotherapists, wardens.
B22: Staff FTE Number of full time equivalent staff, by Staff Group, by Provider, in Accident and Emergency, in NHS Trusts. This is taken as the average over the 4 quarters for financial year 2017-18 from workforce publications (Jun, Sep, Dec 2017 and Mar 2018) to smooth the counts over the year.
... B29: Copyright © 2018, Health and Social Care Information Centre. NHS Digital is the trading name of the Health and Social Care Information Centre.

Sheet National
B1: Experimental Statistics
B6: Supplementary Data Quality Review and Exploratory Analysis of HES A&E Activity and Reported Workforce Statistics
B7: Hospital Episode Statistics (HES) & NHS Hospital & Community Health Service (HCHS) workforce statistics
B8: Please note this analysis and its associated results are neither intended or suitable for any performance monitoring use. The A&E Attendances and Emergency Admissions Monthly Situation Reports (MSitAE) data collected by NHSE are the Official Data source which are used for such purposes.
B11: =Org_Control!A6&", Staff Group (" &Org_Control!B6& ") - Annual 2017 - 18" -> Staff per Attendance / TTS 4 Hour, Staff Group (Consultant) - Annual 2017 - 18 | I11: =Org2_Control!A6&", Staff Group (" &Org2_Control!B6& ") - Annual 2017 - 18" -> Staff per Attendance / TTS 4 Hour, Staff Group (Consultant) - Annual 2017 - 18
B12: Use filters to update one or both scatter plots to facilitate comparison between metrics. National shown as orange.
B13: Avoid removing filter from Measure or Staff Group as this will lose meaning
B40: Remove filter to show all Providers and/or Regions | I40: Remove filter to show all Providers and/or Regions
A50: Key Findings
B52: Number of Staff (FTE) per 1,000 Attendance
A53: - | B53: Nationally for every 1,000 attendances in 2017-18 to A&E there are: 0.75 FTE Nurses 0.09 FTE Consultants 0.24 FTE Doctors (excluding consultants) 0.40 FTE Care Providers (Excluding Doctors and Nurses)
A54: - | B54: Less variation is observed between organisations for the number of whole time equivalent of Consultants and Other Doctors in A&E than is the case for Nurses and Care Provider Groups. The number of organisations within 0.1 FTE per 1,000 attendances for each staff group are: 6 organisations for Nurses (out of 143) 85 organisations for Consultants (out of 135) 7 organisations for Doctors (excluding consultants) (out of 139) 6 organisations for Care Providers (Excluding Doctors and Nurses) (out of 144)
A55: - | B55: Analysis to identify possible relationships between the reported number of staff per 1,000 attendance and the average duration of a patient attendance within A&E demonstrates no strong correlation between these variables across all staff groups.
B56: Staff Stability Index
A57: - | B57: Nationally turnover of staff within A&E departments is lowest amongst Doctors and highest amongst Nurses. The following stability index scores were recorded for each staff group are: 84 per cent for Doctors 77 per cent for Care Providers 73 per cent for Nurses
A58: - | B58: Less variation is observed between organisations for turnover of Doctors in A&E than is the case for Nurses and Care Providers. The number of organisations within 10 per cent of the national stability index score for each staff group are: 86 organisations for Doctors (out of 139) 105 organisations for Care Providers (out of 144) 110 organisations for Nurses (out of 143)
A59: - | B59: Analysis to identify possible relationships between the turnover of staff in A&E and the average duration of a patient attendance within A&E demonstrates no strong correlation between these variables across all staff groups.
B61: Regions
A62: - | B62: There is less observed variation between A&E staff turnover amongst Nurses for Organisations within the London Comissioning Region than in the other NHS Regions. The range in the organisational stability index scores for Nurses in each of the Comissioning Regions are: 19 per cent for London (62% to 81%) 30 per cent for South of England (56% to 86%) 57 per cent for North of England (33% to 90%) 52 per cent for Midlands and East of England (38% to 90%)
A63: - | B63: Less variation is observed between organisations for the number of Care Provider staff per 1,000 A&E attendances in the London Comissioning Region than for other NHS Comissioning Regions. The range of values observed in organisations between each of the NHS Comissioning Regions are: 0.73 for London (0.05 to 0.78) 1.07 for South of England (0.01 to 1.08) 1.24 for North of England (0.10 to 1.34) 0.98 for Midlands and East of England (0.06 to 1.04)

Sheet Provider
B1: Experimental Statistics
B4: Supplementary Data Quality Review and Exploratory Analysis of HES A&E Activity and Reported Workforce Statistics
B5: Hospital Episode Statistics (HES) & NHS Hospital & Community Health Service (HCHS) workforce statistics
B7: Please note this analysis and its associated results are neither intended or suitable for any performance monitoring use. The A&E Attendances and Emergency Admissions Monthly Situation Reports (MSitAE) data collected by NHSE are the Official Data source which are used for such purposes.
B10: Select a Provider to update the summary information below | F10: ="Summary for " &Pivot_table2!A5&" ("&Pivot_table2!B5& ")" -> Summary for Aintree University Hospital NHS Foundation Trust (REM)
F12: ="In 2017-18, there were "&TEXT(Pivot_table2!C5,"00,000")& " A&E attendances of which " &TEXT(Pivot_table2!D5,"0%")& " the total time spent within A&E was 4 hours or less, and "&TEXT(Pivot_table2!E5,"0%")& " had a total time spent within A&E in excess of 12 hours until discharge, transfer or admission." -> In 2017-18, there were 167,270 A&E attendances of which 83% the total time spent within A&E was 4 hours or less, and 2% had a total time spent within A&E in excess of 12 hours until discharge, transfer or admission.
B17: Summary table of Number of FTE Staff, Staff per Attendance Rate and Stability Index, Limited to staff activity recorded as employed within the A&E setting for Selected Provider and Nationally
C19: All Staff | D19: Nurses | E19: Care Providers | F19: Consultants | G19: Doctors (excl. Consultant)
B20: Provider FTE Staff | C20: =SUM(D20:G20) -> 176.93302 | D20: =Pivot_table2!H5 -> 99.479993 | E20: =Pivot_table2!I5 -> 41.416663 | F20: =Pivot_table2!F5 -> 15 | G20: =Pivot_table2!G5 -> 21.036365
B21: Provider Staff per Att Rate | C21: =Pivot_table2!J5 -> 1.057769 | D21: =Pivot_table2!M5 -> 0.59472704 | E21: =Pivot_table2!N5 -> 0.24760365 | F21: =Pivot_table2!K5 -> 0.089675375 | G21: =Pivot_table2!L5 -> 0.12576293
B22: National FTE Staff | C22: 27030.835 | D22: 13739.296 | E22: 7297.8952 | F22: 1642.0239 | G22: 4351.6203
B23: National Staff per Att Rate | C23: 1.4719916 | D23: 0.74818732 | E23: 0.3974143 | F23: 0.089418081 | G23: 0.2369719
C24: All Staff | D24: Nurses | E24: Care Providers | F24: Doctors (All)
B25: Provider Stability Index | C25: =Pivot_table2!Q5 -> 0.75324675 | D25: =Pivot_table2!R5 -> 0.7173913 | E25: =Pivot_table2!O5 -> 0.79545455 | F25: =Pivot_table2!P5 -> 0.83333333
B26: National Stability Index | C26: 0.75814184 | D26: 0.726593 | E26: 0.77174 | F26: 0.84366472

Sheet data
H1: Measure | I1: Stability Index / 4 Hour Wait
A2: Org | B2: Measure | C2: Staff Group | D2: Date Period | E2: Rates | F2: 4 hour wait | H2: Date Period | I2: Annual 2017/18 Total
A3: Trust 1 | B3: Stability Index / 12 Hour Wait | C3: Doctors | D3: Annual 2017/18 Total | E3: 0.50793651 | F3: 0.66911765 | H3: Staff Group | I3: Doctors
A4: Trust 1 | B4: Stability Index / 12 Hour Wait | C4: Clinical Staff | D4: Annual 2017/18 Total | E4: 0.1025641 | F4: 0.36065574
A5: Trust 1 | B5: Stability Index / 12 Hour Wait | C5: Support Staff | D5: Annual 2017/18 Total | E5: 0.15116279 | F5: 0.34868421 | H5: Count of Org | I5: Column Labels
A6: Trust 1 | B6: Stability Index / 4 Hour Wait | C6: Doctors | D6: Annual 2017/18 Total | E6: 0.16551724 | F6: 0.68627451 | H6: Row Labels | I6: 0.10447761 | J6: 0.12565445 | K6: 0.2979798 | L6: 0.34810127 | M6: 0.68627451 | N6: Grand Total
A7: Trust 1 | B7: Stability Index / 12 Hour Wait | C7: Clinical Staff | D7: Q1 2017/18 | E7: 0.18125 | F7: 0.65277778 | H7: 0.16551724 | M7: 1 | N7: 1
A8: Trust 1 | B8: Stability Index / 12 Hour Wait | C8: Support Staff | D8: Q1 2017/18 | E8: 0.14503817 | F8: 0.10606061 | H8: 0.2585034 | L8: 1 | N8: 1
A9: Trust 1 | B9: Staff Per Attendance / 12 Hour Wait | C9: Doctors | D9: Annual 2017/18 Total | E9: 0.47120419 | F9: 0.032258065 | H9: 0.58778626 | I9: 1 | N9: 1
A10: Trust 1 | B10: Stability Index / 12 Hour Wait | C10: Clinical Staff | D10: Q2 2017/18 | E10: 0.041666667 | F10: 0.35114504 | H10: 0.70175439 | J10: 1 | N10: 1
A11: Trust 1 | B11: Stability Index / 12 Hour Wait | C11: Support Staff | D11: Q2 2017/18 | E11: 0.4084507 | F11: 0.31343284 | H11: 0.75221239 | K11: 1 | N11: 1
A12: Trust 1 | B12: Staff Per Attendance / 4 Hour Wait | C12: Doctors | D12: Annual 2017/18 Total | E12: 0.29245283 | F12: 0.52631579 | H12: Grand Total | I12: 1 | J12: 1 | K12: 1 | L12: 1 | M12: 1 | N12: 5
A13: Trust 1 | B13: Stability Index / 12 Hour Wait | C13: Clinical Staff | D13: Q3 2017/25 | E13: 0.36065574 | F13: 0.79508197
A14: Trust 1 | B14: Stability Index / 12 Hour Wait | C14: Support Staff | D14: Q3 2017/29 | E14: 0.48795181 | F14: 0.62280702
A15: Trust 2 | B15: Stability Index / 12 Hour Wait | C15: Doctors | D15: Annual 2017/18 Total | E15: 0.51111111 | F15: 0.776
A16: Trust 1 | B16: Stability Index / 12 Hour Wait | C16: Clinical Staff | D16: Q4 2017/25 | E16: 0.22772277 | F16: 0.65277778
A17: Trust 1 | B17: Stability Index / 12 Hour Wait | C17: Support Staff | D17: Q4 2017/29 | E17: 0.44247788 | F17: 0.42857143
A18: Trust 2 | B18: Stability Index / 4 Hour Wait | C18: Doctors | D18: Annual 2017/18 Total | E18: 0.58778626 | F18: 0.10447761
A19: Trust 1 | B19: Stability Index / 4 Hour Wait | C19: Clinical Staff | D19: Annual 2017/18 Total | E19: 0.8411215 | F19: 0.18181818
A20: Trust 1 | B20: Stability Index / 4 Hour Wait | C20: Support Staff | D20: Annual 2017/18 Total | E20: 0.17277487 | F20: 0.085470085
A21: Trust 2 | B21: Staff Per Attendance / 12 Hour Wait | C21: Doctors | D21: Annual 2017/18 Total | E21: 0.087837838 | F21: 0.45728643
A22: Trust 1 | B22: Stability Index / 4 Hour Wait | C22: Clinical Staff | D22: Q1 2017/18 | E22: 0.092307692 | F22: 0.18238994
A23: Trust 1 | B23: Stability Index / 4 Hour Wait | C23: Support Staff | D23: Q1 2017/18 | E23: 0.11458333 | F23: 0.36423841
A24: Trust 2 | B24: Staff Per Attendance / 4 Hour Wait | C24: Doctors | D24: Annual 2017/18 Total | E24: 0.14124294 | F24: 0.2601626
... A302: Trust 5 | B302: Staff Per Attendance / 4 Hour Wait | C302: Support Staff | D302: Q4 2017/26 | E302: 0.52147239 | F302: 0.60625

Sheet Staff FTE_1
A1: Org name | B1: Org code | C1: Consultant | D1: Doctor (excl. Consultant) | E1: Nurse | F1: Clinical (excl. Doctor and Nurse) | G1: 4hr % | H1: 12hr %
A2: Aintree University Hospital NHS Foundation Trust | B2: REM | C2: 0.089674839 | D2: 0.12576218 | E2: 0.59472349 | F2: 0.24760217 | G2: 0.82522374 | H2: 0.020254557
A3: Airedale NHS Foundation Trust | B3: RCF | C3: 0.1322084 | D3: 0.30222558 | E3: 0.67101548 | F3: 0.49978268 | G3: 0.9188136 | H3: 0.0010611464
A4: Alder Hey Children's NHS Foundation Trust | B4: RBS | C4: 0.13675784 | D4: 0.086424283 | E4: 0.71978515 | F4: 0.09528569 | G4: 0.94863242 | H4: 5.0033356e-05
A5: Ashford and St. Peter's Hospitals NHS Foundation Trust | B5: RTK | C5: 0.066733235 | D5: 0.14088127 | E5: 0.690598 | F5: 0.28933487 | G5: 0.8499738 | H5: 0.030153536
A6: Barking, Havering and Redbridge University Hospitals NHS Trust | B6: RF4 | C6: 0.032908655 | D6: 0.14671775 | E6: 0.54991198 | F6: 0.25461738 | G6: 0.79653049 | H6: 0.025982167
A7: Barnsley Hospital NHS Foundation Trust | B7: RFF | C7: 0.14782713 | D7: 0.25809054 | E7: 0.75515597 | F7: 0.45850386 | G7: 0.90477248 | H7: 0.0049221344
A8: Barts Health NHS Trust | B8: R1H | C8: 0.10633967 | D8: 0.27671184 | E8: 0.68619463 | F8: 0.32095069 | G8: 0.81488207 | H8: 0.012760761
A9: Basildon and Thurrock University Hospitals NHS Foundation Trust | B9: RDD | C9: 0.068707412 | D9: 0.26674642 | E9: 0.46739888 | F9: 0.38368373 | G9: 0.85812324 | H9: 0.025745071
A10: Bedford Hospital NHS Trust | B10: RC1 | C10: 0.072432276 | D10: 0.28090142 | E10: 0.64754491 | F10: 0.23266126 | G10: 0.90379677 | H10: 0.0024890364
A11: Birmingham Women's and Children's NHS Foundation Trust | B11: RQ3 | C11: 0.093394785 | D11: 0.3168077 | E11: 0.83334744 | F11: 0.27065599 | G11: 0.92844071 | H11: 0.00052049228
A12: Blackpool Teaching Hospitals NHS Foundation Trust | B12: RXL | C12: 0.087850461 | D12: 0.3752257 | E12: 0.98986025 | F12: 0.57979747 | G12: 0.59016702 | H12: 0.072863376
A13: Bolton NHS Foundation Trust | B13: RMC | C13: 0.091906079 | D13: 0.2594386 | E13: 0.86695128 | F13: 0.26093075 | G13: 0.8150832 | H13: 0.0062566831
... A34: East Kent Hospitals University NHS Foundation Trust | B34: RVV | C34: 0.056241532 | D34: 0.16880448 | E34: 0.96172063 | F34: 0.7183408 | G34: 0.70319299 | H34: 0.050474218
A35: East Lancashire Hospitals NHS Trust | B35: RXR | C35: #DIV/0! | D35: 0.067950203 | E35: 0.098166436 | F35: 0.13602656 | G35: 0.79475256 | H35: 0.01634297
A36: East Sussex Healthcare NHS Trust | B36: RXC | C36: 0.073545018 | D36: 0.28200216 | E36: 0.79949735 | F36: 0.44982572 | G36: 0.78580464 | H36: 0.040556947
A37: Epsom and St Helier University Hospitals NHS Trust | B37: RVR | C37: 0.076228413 | D37: 0.26517756 | E37: 0.65112388 | F37: 0.25869632 | G37: 0.92594491 | H37: 0.007544991
A38: Frimley Health NHS Foundation Trust | B38: RDU | C38: 0.095993558 | D38: 0.30161925 | E38: 0.83782846 | F38: 0.35178608 | G38: 0.88981919 | H38: 0.011706659
A39: Gateshead Health NHS Foundation Trust | B39: RR7 | C39: 0.07006631 | D39: 0.1990864 | E39: 0.60301377 | F39: 0.28269296 | G39: 0.946174 | H39: 0.00026800612
A40: George Eliot Hospital NHS Trust | B40: RLT | C40: 0.066389527 | D40: 0.07569647 | E40: 0.70670733 | F40: 0.34623891 | G40: 0.87775641 | H40: 0.023614817
A41: Gloucestershire Hospitals NHS Foundation Trust | B41: RTE | C41: 0.13663717 | D41: 0.21946903 | E41: 0.82636027 | F41: 0.33903451 | G41: 0.86700177 | H41: 0.0028743363
A42: Great Western Hospitals NHS Foundation Trust | B42: RN3 | C42: 0.088328564 | D42: 0.20343789 | E42: 0.5420521 | F42: 0.42059019 | G42: 0.84341256 | H42: 0.02840914
A43: Guy's and St Thomas' NHS Foundation Trust | B43: RJ1 | C43: 0.13430039 | D43: 0.37362923 | E43: 0.94034988 | F43: 0.27941774 | G43: 0.86287063 | H43: 0.00073292615
A44: Hampshire Hospitals NHS Foundation Trust | B44: RN5 | C44: 0.092877507 | D44: 0.24181299 | E44: 0.84292384 | F44: 0.39984479 | G44: 0.86811394 | H44: 0.0095704213
A45: Harrogate and District NHS Foundation Trust | B45: RCD | C45: 0.12276447 | D45: 0.45623042 | E45: 0.64255173 | F45: 0.39426079 | G45: 0.94180055 | H45: 0.00018187329
A46: Hillingdon Hospitals NHS Foundation Trust | B46: RAS | C46: 0.10035896 | D46: 0.30293537 | E46: 0.8411746 | F46: 0.37905928 | G46: 0.74292177 | H46: 0.031753786
A47: Homerton University Hospital NHS Foundation Trust | B47: RQX | C47: 0.081845726 | D47: 0.27844205 | E47: 0.52752993 | F47: 0.18960087 | G47: 0.73223891 | H47: 0.032020795
A48: Hounslow and Richmond Community Healthcare NHS Trust | B48: RY9 | C48: #DIV/0! | D48: 0.00044521353 | E48: 0.057071879 | F48: 0.047995298 | G48: 0.99276479 | H48: 5.2239781e-05
A49: Hull and East Yorkshire Hospitals NHS Trust | B49: RWA | C49: 0.11071066 | D49: 0.24823672 | E49: 0.62872303 | F49: 0.21149717 | G49: 0.87165739 | H49: 0.0048167653
A50: Imperial College Healthcare NHS Trust | B50: RYJ | C50: 0.1058276 | D50: 0.32465808 | E50: 0.67880692 | F50: 0.2477713 | G50: 0.8313508 | H50: 0.015411665
A51: Ipswich Hospital NHS Trust | B51: RGQ | C51: 0.13890548 | D51: 0.36335394 | E51: 0.84506412 | F51: 0.44500312 | G51: 0.90717909 | H51: 0.00034760317
A52: Isle of Wight NHS Trust | B52: R1F | C52: 0.080489375 | D52: 0.23844977 | E52: 0.50107997 | F52: 0.34399152 | G52: 0.82650515 | H52: 0.025253542
A53: James Paget University Hospitals NHS Foundation Trust | B53: RGP | C53: 0.062667166 | D53: 0.1613518 | E53: 0.62245688 | F53: 0.29777538 | G53: 0.9049268 | H53: 0.013089039
A54: Kent Community Health NHS Foundation Trust | B54: RYY | C54: #DIV/0! | D54: 0 | E54: 0.023782378 | F54: 0.0094429945 | G54: 0.99832125 | H54: 9.1806891e-05
A55: Kettering General Hospital NHS Foundation Trust | B55: RNQ | C55: 0.069054415 | D55: 0.27995811 | E55: 0.80112705 | F55: 0.58243561 | G55: 0.76826489 | H55: 0.034630789
A56: King's College Hospital NHS Foundation Trust | B56: RJZ | C56: 0.099609007 | D56: 0.33404592 | E56: 1.2698922 | F56: 0.21676373 | G56: 0.77614901 | H56: 0.027741656
A57: Kingston Hospital NHS Foundation Trust | B57: RAX | C57: 0.083558435 | D57: 0.20000064 | E57: 0.62518505 | F57: 0.32480566 | G57: 0.79727142 | H57: 0.01388224
A58: Lancashire Teaching Hospitals NHS Foundation Trust | B58: RXN | C58: 0.20774791 | D58: 0.37183069 | E58: 0.9720992 | F58: 0.69252853 | G58: 0.75357687 | H58: 0.025558249
A59: Leeds Teaching Hospitals NHS Trust | B59: RR8 | C59: 0.14925654 | D59: 0.24793433 | E59: 1.0304198 | F59: 0.64274742 | G59: 0.80601818 | H59: 0.024232459
A60: Lewisham and Greenwich NHS Trust | B60: RJ2 | C60: 0.081581614 | D60: 0.30165296 | E60: 0.97220869 | F60: 0.33092317 | G60: 0.80135923 | H60: 0.035788994
...

Sheet Staff FTE_2
A1: Org name | B1: Org code | C1: Measure | D1: Staff Group | E1: Staff Rate | F1: Measure Rate
A2: Aintree University Hospital NHS Foundation Trust | B2: REM | C2: Staff per Attendance / 4 Hour Wait | D2: Consultant | E2: 0.089674839 | F2: 0.82522374
A3: Airedale NHS Foundation Trust | B3: RCF | C3: Staff per Attendance / 4 Hour Wait | D3: Consultant | E3: 0.1322084 | F3: 0.9188136
A4: Alder Hey Children's NHS Foundation Trust | B4: RBS | C4: Staff per Attendance / 4 Hour Wait | D4: Consultant | E4: 0.13675784 | F4: 0.94863242
A5: Ashford and St. Peter's Hospitals NHS Foundation Trust | B5: RTK | C5: Staff per Attendance / 4 Hour Wait | D5: Consultant | E5: 0.066733235 | F5: 0.8499738
A6: Barking, Havering and Redbridge University Hospitals NHS Trust | B6: RF4 | C6: Staff per Attendance / 4 Hour Wait | D6: Consultant | E6: 0.032908655 | F6: 0.79653049
A7: Barnsley Hospital NHS Foundation Trust | B7: RFF | C7: Staff per Attendance / 4 Hour Wait | D7: Consultant | E7: 0.14782713 | F7: 0.90477248
A8: Barts Health NHS Trust | B8: R1H | C8: Staff per Attendance / 4 Hour Wait | D8: Consultant | E8: 0.10633967 | F8: 0.81488207
A9: Basildon and Thurrock University Hospitals NHS Foundation Trust | B9: RDD | C9: Staff per Attendance / 4 Hour Wait | D9: Consultant | E9: 0.068707412 | F9: 0.85812324
A10: Bedford Hospital NHS Trust | B10: RC1 | C10: Staff per Attendance / 4 Hour Wait | D10: Consultant | E10: 0.072432276 | F10: 0.90379677
A11: Birmingham Women's and Children's NHS Foundation Trust | B11: RQ3 | C11: Staff per Attendance / 4 Hour Wait | D11: Consultant | E11: 0.093394785 | F11: 0.92844071
A12: Blackpool Teaching Hospitals NHS Foundation Trust | B12: RXL | C12: Staff per Attendance / 4 Hour Wait | D12: Consultant | E12: 0.087850461 | F12: 0.59016702
A13: Bolton NHS Foundation Trust | B13: RMC | C13: Staff per Attendance / 4 Hour Wait | D13: Consultant | E13: 0.091906079 | F13: 0.8150832
... A34: East Kent Hospitals University NHS Foundation Trust | B34: RVV | C34: Staff per Attendance / 4 Hour Wait | D34: Consultant | E34: 0.056241532 | F34: 0.70319299
A35: East Lancashire Hospitals NHS Trust | B35: RXR | C35: Staff per Attendance / 4 Hour Wait | D35: Consultant | E35: #DIV/0! | F35: 0.79475256
A36: East Sussex Healthcare NHS Trust | B36: RXC | C36: Staff per Attendance / 4 Hour Wait | D36: Consultant | E36: 0.073545018 | F36: 0.78580464
A37: Epsom and St Helier University Hospitals NHS Trust | B37: RVR | C37: Staff per Attendance / 4 Hour Wait | D37: Consultant | E37: 0.076228413 | F37: 0.92594491
A38: Frimley Health NHS Foundation Trust | B38: RDU | C38: Staff per Attendance / 4 Hour Wait | D38: Consultant | E38: 0.095993558 | F38: 0.88981919
A39: Gateshead Health NHS Foundation Trust | B39: RR7 | C39: Staff per Attendance / 4 Hour Wait | D39: Consultant | E39: 0.07006631 | F39: 0.946174
A40: George Eliot Hospital NHS Trust | B40: RLT | C40: Staff per Attendance / 4 Hour Wait | D40: Consultant | E40: 0.066389527 | F40: 0.87775641
A41: Gloucestershire Hospitals NHS Foundation Trust | B41: RTE | C41: Staff per Attendance / 4 Hour Wait | D41: Consultant | E41: 0.13663717 | F41: 0.86700177
A42: Great Western Hospitals NHS Foundation Trust | B42: RN3 | C42: Staff per Attendance / 4 Hour Wait | D42: Consultant | E42: 0.088328564 | F42: 0.84341256
A43: Guy's and St Thomas' NHS Foundation Trust | B43: RJ1 | C43: Staff per Attendance / 4 Hour Wait | D43: Consultant | E43: 0.13430039 | F43: 0.86287063
A44: Hampshire Hospitals NHS Foundation Trust | B44: RN5 | C44: Staff per Attendance / 4 Hour Wait | D44: Consultant | E44: 0.092877507 | F44: 0.86811394
A45: Harrogate and District NHS Foundation Trust | B45: RCD | C45: Staff per Attendance / 4 Hour Wait | D45: Consultant | E45: 0.12276447 | F45: 0.94180055
A46: Hillingdon Hospitals NHS Foundation Trust | B46: RAS | C46: Staff per Attendance / 4 Hour Wait | D46: Consultant | E46: 0.10035896 | F46: 0.74292177
A47: Homerton University Hospital NHS Foundation Trust | B47: RQX | C47: Staff per Attendance / 4 Hour Wait | D47: Consultant | E47: 0.081845726 | F47: 0.73223891
A48: Hounslow and Richmond Community Healthcare NHS Trust | B48: RY9 | C48: Staff per Attendance / 4 Hour Wait | D48: Consultant | E48: #DIV/0! | F48: 0.99276479
A49: Hull and East Yorkshire Hospitals NHS Trust | B49: RWA | C49: Staff per Attendance / 4 Hour Wait | D49: Consultant | E49: 0.11071066 | F49: 0.87165739
A50: Imperial College Healthcare NHS Trust | B50: RYJ | C50: Staff per Attendance / 4 Hour Wait | D50: Consultant | E50: 0.1058276 | F50: 0.8313508
A51: Ipswich Hospital NHS Trust | B51: RGQ | C51: Staff per Attendance / 4 Hour Wait | D51: Consultant | E51: 0.13890548 | F51: 0.90717909
A52: Isle of Wight NHS Trust | B52: R1F | C52: Staff per Attendance / 4 Hour Wait | D52: Consultant | E52: 0.080489375 | F52: 0.82650515
A53: James Paget University Hospitals NHS Foundation Trust | B53: RGP | C53: Staff per Attendance / 4 Hour Wait | D53: Consultant | E53: 0.062667166 | F53: 0.9049268
A54: Kent Community Health NHS Foundation Trust | B54: RYY | C54: Staff per Attendance / 4 Hour Wait | D54: Consultant | E54: #DIV/0! | F54: 0.99832125
A55: Kettering General Hospital NHS Foundation Trust | B55: RNQ | C55: Staff per Attendance / 4 Hour Wait | D55: Consultant | E55: 0.069054415 | F55: 0.76826489
A56: King's College Hospital NHS Foundation Trust | B56: RJZ | C56: Staff per Attendance / 4 Hour Wait | D56: Consultant | E56: 0.099609007 | F56: 0.77614901
A57: Kingston Hospital NHS Foundation Trust | B57: RAX | C57: Staff per Attendance / 4 Hour Wait | D57: Consultant | E57: 0.083558435 | F57: 0.79727142
A58: Lancashire Teaching Hospitals NHS Foundation Trust | B58: RXN | C58: Staff per Attendance / 4 Hour Wait | D58: Consultant | E58: 0.20774791 | F58: 0.75357687
A59: Leeds Teaching Hospitals NHS Trust | B59: RR8 | C59: Staff per Attendance / 4 Hour Wait | D59: Consultant | E59: 0.14925654 | F59: 0.80601818
A60: Lewisham and Greenwich NHS Trust | B60: RJ2 | C60: Staff per Attendance / 4 Hour Wait | D60: Consultant | E60: 0.081581614 | F60: 0.80135923
...

Sheet stability_1
A1: Organisation name | B1: Organisation code | C1: Doctor | D1: Nurse | E1: Clinical (excl. Doctor and Nurse) | F1: 4hr% or less (<=) | G1: Over 12hr% (>)
A2: Derby Teaching Hospitals NHS Foundation Trust | B2: RTG | C2: 0.92307692 | D2: 0.8013245 | E2: 0.87628866 | F2: 0.81002094 | G2: 0.0011558004
A3: Kettering General Hospital NHS Foundation Trust | B3: RNQ | C3: 0.86363636 | D3: 0.73333333 | E3: 0.69565217 | F3: 0.76826489 | G3: 0.034630789
A4: Lincolnshire Community Health Services NHS Trust | B4: RY5 | D4: 0.375 | E4: 0.88235294 | F4: 0.99053911 | G4: 0.00012260328
A5: Northampton General Hospital NHS Trust | B5: RNS | C5: 0.91666667 | D5: 0.77669903 | E5: 0.68627451 | F5: 0.85110462 | G5: 0.034843689
A6: Nottingham University Hospitals NHS Trust | B6: RX1 | C6: 1 | D6: 0.71031746 | E6: 0.79439252 | F6: 0.79868085 | G6: 0.0099516547
A7: Sherwood Forest Hospitals NHS Foundation Trust | B7: RK5 | C7: 0.625 | D7: 0.8125 | E7: 0.84722222 | F7: 0.90903148 | G7: 0.0017732815
A8: United Lincolnshire Hospitals NHS Trust | B8: RWD | C8: 0.88461538 | D8: 0.78142077 | E8: 0.83333333 | F8: 0.73940222 | G8: 0.023319848
A9: University Hospitals of Leicester NHS Trust | B9: RWE | C9: 0.83333333 | D9: 0.77922078 | E9: 0.7443609 | F9: 0.77543447 | G9: 0.012108671
A10: Basildon and Thurrock University Hospitals NHS Foundation Trust | B10: RDD | C10: 0.95 | D10: 0.65625 | E10: 0.78181818 | F10: 0.85812324 | G10: 0.025745071
A11: Bedford Hospital NHS Trust | B11: RC1 | C11: 1 | D11: 0.82978723 | E11: 0.8125 | F11: 0.90379677 | G11: 0.0024890364
A12: Cambridge University Hospitals NHS Foundation Trust | B12: RGT | C12: 0.9 | D12: 0.78395062 | E12: 0.725 | F12: 0.89118556 | G12: 0.0027384785
A13: Colchester Hospital University NHS Foundation Trust | B13: RDE | C13: 0.86363636 | D13: 0.82191781 | E13: 0.71428571 | F13: 0.8257062 | G13: 0.016790676
A14: East and North Hertfordshire NHS Trust | B14: RWH | C14: 0.75 | D14: 0.85074627 | E14: 0.7254902 | F14: 0.80487735 | G14: 0.019416574
A15: Ipswich Hospital NHS Trust | B15: RGQ | C15: 0.7826087 | D15: 0.81609195 | E15: 0.79166667 | F15: 0.90717909 | G15: 0.00034760317
A16: James Paget University Hospitals NHS Foundation Trust | B16: RGP | C16: 0.86666667 | D16: 0.89795918 | E16: 0.91666667 | F16: 0.9049268 | G16: 0.013089039
... A46: Salisbury NHS Foundation Trust | B46: RNZ | C46: 0.7 | D46: 0.7173913 | E46: 0.91304348 | F46: 0.91707222 | G46: 0.0025955486
A47: Southern Health NHS Foundation Trust | B47: RW1 | D47: 0.85714286 | E47: 0.85714286 | F47: 0.99685905 | G47: 6.5436461e-05
A48: University Hospital Southampton NHS Foundation Trust | B48: RHM | C48: 0.875 | D48: 0.74468085 | E48: 0.5 | F48: 0.87863591 | G48: 0.0031427616
A49: Buckinghamshire Healthcare NHS Trust | B49: RXQ | C49: 0.8125 | D49: 0.60273973 | E49: 0.66666667 | F49: 0.75078388 | G49: 0.054356533
A50: Milton Keynes University Hospital NHS Foundation Trust | B50: RD8 | C50: 1 | D50: 0.80645161 | E50: 0.85 | F50: 0.85303573 | G50: 0.022079085
A51: Oxford University Hospitals NHS Foundation Trust | B51: RTH | C51: 0.96 | D51: 0.73758865 | E51: 0.86170213 | F51: 0.80364548 | G51: 0.03799153
A52: Royal Berkshire NHS Foundation Trust | B52: RHW | C52: 0.84615385 | D52: 0.69148936 | E52: 0.76 | F52: 0.88420922 | G52: 0.0047803888
A53: Chelsea and Westminster Hospital NHS Foundation Trust | B53: RQM | C53: 0.77777778 | D53: 0.76646707 | E53: 0.6 | F53: 0.87054495 | G53: 0.0054383916
A54: Hillingdon Hospitals NHS Foundation Trust | B54: RAS | C54: 0.88 | D54: 0.76744186 | E54: 0.6 | F54: 0.74292177 | G54: 0.031753786
A55: Hounslow and Richmond Community Healthcare NHS Trust | B55: RY9 | C55: 0 | D55: 0.66666667 | E55: 0.77777778 | F55: 0.99276479 | G55: 5.2239781e-05
A56: Imperial College Healthcare NHS Trust | B56: RYJ | C56: 0.85185185 | D56: 0.69411765 | E56: 0.6875 | F56: 0.8313508 | G56: 0.015411665
A57: London North West University Healthcare NHS Trust | B57: R1K | C57: 0.87878788 | D57: 0.74568966 | E57: 0.75423729 | F57: 0.58551534 | G57: 0.078225423
A58: Croydon Health Services NHS Trust | B58: RJ6 | C58: 0.88888889 | D58: 0.61956522 | E58: 0.73913043 | F58: 0.89180482 | G58: 0.0097667125
A59: Epsom and St Helier University Hospitals NHS Trust | B59: RVR | C59: 0.85714286 | D59: 0.73636364 | E59: 0.6875 | F59: 0.92594491 | G59: 0.007544991
... A77: Frimley Health NHS Foundation Trust | B77: RDU | C77: 0.78125 | D77: 0.76271186 | E77: 0.82291667 | F77: 0.88981919 | G77: 0.011706659
A78: Kent Community Health NHS Foundation Trust | B78: RYY | D78: 0.66666667 | E78: 1 | F78: 0.99832125 | G78: 9.1806891e-05
A79: Maidstone and Tunbridge Wells NHS Trust | B79: RWF | C79: 0.88888889 | D79: 0.69127517 | E79: 0.80597015 | F79: 0.89224885 | G79: 0.030786043
A80: Medway NHS Foundation Trust | B80: RPA | C80: 0.95652174 | D80: 0.82539683 | E80: 0.48571429 | F80: 0.83415204 | G80: 0.039388479
A81: Queen Victoria Hospital NHS Foundation Trust | B81: RPC | C81: 0 | E81: 0.77777778 | F81: 0.99689441 | G81: 0
A82: Royal Surrey County Hospital NHS Foundation Trust | B82: RA2 | C82: 0.66666667 | D82: 0.84057971 | E82: 0.70588235 | F82: 0.94885531 | G82: 0.0022978459
A83: Surrey and Sussex Healthcare NHS Trust | B83: RTP | C83: 0.78571429 | D83: 0.73626374 | E83: 0.70212766 | F83: 0.91327326 | G83: 0.034403159
A84: Western Sussex Hospitals NHS Foundation Trust | B84: RYR | C84: 0.91304348 | D84: 0.76190476 | E84: 0.76190476 | F84: 0.91622699 | G84: 0.0027699613
A85: City Hospitals Sunderland NHS Foundation Trust | B85: RLN | C85: 0.92307692 | D85: 0.84090909 | E85: 0.97058824 | F85: 0.91211079 | G85: 0.00046965639
A86: County Durham and Darlington NHS Foundation Trust | B86: RXP | C86: 0.86363636 | D86: 0.8411215 | E86: 0.81666667 | F86: 0.91409366 | G86: 0.0051388829
...

Sheet Timeseries_data
A1: Rate of: | B1: 2009-10 | C1: 2010-11 | D1: 2011-12 | E1: 2012-13 | F1: 2013-14 | G1: 2014-15 | H1: 2015-16 | I1: 2016-17 | J1: 2017-18
A2: Doctors | B2: 0.30123449 | C2: 0.30269764 | D2: 0.28023798 | E2: 0.27911374 | F2: 0.28325948 | G2: 0.28279896 | H2: 0.27271965 | I2: 0.2890925 | J2: 0.28506735 | L2: Bar chart
A3: Nurses | B3: 0.70466503 | C3: 0.70067787 | D3: 0.66028262 | E3: 0.6456685 | F3: 0.65655776 | G3: 0.64282129 | H3: 0.6345127 | I3: 0.6540814 | J3: 0.65847189 | L3: Bar chart
A4: Other clinical staff | B4: 0.4878615 | C4: 0.52897426 | D4: 0.4956074 | E4: 0.48776872 | F4: 0.50932515 | G4: 0.50892144 | H4: 0.49623361 | I4: 0.5284162 | J4: 0.52913798 | L4: Bar chart
A5: 4 hour target | B5: 0.95778446 | C5: 0.9423444 | D5: 0.94578255 | E5: 0.94230986 | F5: 0.9365582 | G5: 0.9137216 | H5: 0.89127036 | I5: 0.86271758 | J5: 0.85473868 | L5: line
A8: Rate of: | B8: 2009-10 | C8: 2010-11 | D8: 2011-12 | E8: 2012-13 | F8: 2013-14 | G8: 2014-15 | H8: 2015-16 | I8: 2016-17 | J8: 2017-18
A9: Doctors | B9: 0.30123449 | C9: 0.30269764 | D9: 0.28023798 | E9: 0.27911374 | F9: 0.28325948 | G9: 0.28279896 | H9: 0.27271965 | I9: 0.2890925 | J9: 0.28506735 | L9: Bar chart
A10: Nurses | B10: 0.70466503 | C10: 0.70067787 | D10: 0.66028262 | E10: 0.6456685 | F10: 0.65655776 | G10: 0.64282129 | H10: 0.6345127 | I10: 0.6540814 | J10: 0.65847189 | L10: Bar chart
A11: Other clinical staff | B11: 0.4878615 | C11: 0.52897426 | D11: 0.4956074 | E11: 0.48776872 | F11: 0.50932515 | G11: 0.50892144 | H11: 0.49623361 | I11: 0.5284162 | J11: 0.52913798 | L11: Bar chart
A12: 12 hour target | B12: 0.0035421336 | C12: 0.0086652339 | D12: 0.0033388775 | E12: 0.0036537856 | F12: 0.0056369189 | G12: 0.0089369158 | H12: 0.0097734186 | I12: 0.012733929 | J12: 0.015848071 | L12: line
A14: Total Unplanned | B14: 15079612 | C14: 15818846 | D14: 17286648 | E14: 18005435 | F14: 18197530 | G14: 19254853 | H14: 20168071 | I14: 20603774 | J14: 21011705
A15: <= 4 hours wait | B15: 14443018 | C15: 14906801 | D15: 16349410 | E15: 16966699 | F15: 17043046 | G15: 17593575 | H15: 17975204 | I15: 17775238 | J15: 17959517
A16: Over 12 hours wait | B16: 53414 | C16: 137074 | D16: 57718 | E16: 65788 | F16: 102578 | G16: 172079 | H16: 197111 | I16: 262367 | J16: 332995 | L16: Summary Report 9
A18: NHS Trusts and CCGs, as at the last day of September
A19: FTE | B19: 40057 | C19: 40422 | D19: 40787 | E19: 41153 | F19: 41518 | G19: 41883 | H19: 42248 | I19: 42614 | J19: 42979
A20: HCHS Doctors | B20: 4542.4993 | C20: 4788.3273 | D20: 4844.3753 | E20: 5025.5643 | F20: 5154.6228 | G20: 5445.2524 | H20: 5500.2292 | I20: 5956.3966 | J20: 5989.751
A21: Nurses & health visitors | B21: 10626.075 | C21: 11083.915 | D21: 11414.073 | E21: 11625.542 | F21: 11947.73 | G21: 12377.43 | H21: 12796.897 | I21: 13476.545 | J21: 13835.617
A22: Total clinical staff exl doctors and nurses | B22: 7356.7622 | C22: 8367.7624 | D22: 8567.3906 | E22: 8782.4879 | F22: 9268.4597 | G22: 9799.2075 | H22: 10008.075 | I22: 10887.368 | J22: 11118.091

Sheet Org_Control
A5: Measure | B5: Staff Group
A6: Staff per Attendance / TTS 4 Hour | B6: Consultant
B7: Doctor (excl. Consultant)
B8: Nurse
B9: Care Provider (excl. Doctor and Nurse)
A10: Staff per Attendance / TTS 4 Hour Total
A11: Staff per Attendance / TTS 12 Hour | B11: Consultant
B12: Doctor (excl. Consultant)
B13: Nurse
B14: Care Provider (excl. Doctor and Nurse)
A15: Staff per Attendance / TTS 12 Hour Total
A16: Stability Index / TTS 4 Hour | B16: Doctor
B17: Nurse
B18: Care Provider (excl. Doctor and Nurse)
A19: Stability Index / TTS 4 Hour Total
A20: Stability Index / TTS 12 Hour | B20: Doctor
B21: Nurse
B22: Care Provider (excl. Doctor and Nurse)
A23: Stability Index / TTS 12 Hour Total

Sheet Pivot_tables
A1: Select Measure | B1: (All) | E1: National | F1: =VLOOKUP(E1,E5:G226,2,FALSE) -> 7.6279785 | G1: =VLOOKUP(E1,E5:G211,3,FALSE) -> 6.0326221
A2: Selelct Staff Group | B2: (All)
B4: Values
A5: Organisation name | B5: Sum of Staff Rate | C5: Sum of Measure Rate | E5: =A5 -> Organisation name | F5: =B5 -> Sum of Staff Rate | G5: =C5 -> Sum of Measure Rate
A6: Aintree University Hospital NHS Foundation Trust | B6: 6.8078964 | C6: 5.9184253 | E6: =IF(A6="",NA(),A6) -> Aintree University Hospital NHS Foundation Trust | F6: =IF(B6="",NA(),B6) -> 6.8078964 | G6: =IF(C6="",NA(),C6) -> 5.9184253
A7: Airedale NHS Foundation Trust | B7: 8.4882421 | C7: 6.439245 | E7: =IF(A7="",NA(),A7) -> Airedale NHS Foundation Trust | F7: =IF(B7="",NA(),B7) -> 8.4882421 | G7: =IF(C7="",NA(),C7) -> 6.439245
A8: Alder Hey Children's NHS Foundation Trust | B8: 6.9820615 | C8: 6.640427 | E8: =IF(A8="",NA(),A8) -> Alder Hey Children's NHS Foundation Trust | F8: =IF(B8="",NA(),B8) -> 6.9820615 | G8: =IF(C8="",NA(),C8) -> 6.640427
A9: Ashford and St. Peter's Hospitals NHS Foundation Trust | B9: 7.4131313 | C9: 6.1608997 | E9: =IF(A9="",NA(),A9) -> Ashford and St. Peter's Hospitals NHS Foundation Trust | F9: =IF(B9="",NA(),B9) -> 7.4131313 | G9: =IF(C9="",NA(),C9) -> 6.1608997
A10: Barking, Havering and Redbridge University Hospitals NHS Trust | B10: 6.1752534 | C10: 5.7575514 | E10: =IF(A10="",NA(),A10) -> Barking, Havering and Redbridge University Hospitals NHS Trust | F10: =IF(B10="",NA(),B10) -> 6.1752534 | G10: =IF(C10="",NA(),C10) -> 5.7575514
A11: Barnsley Hospital NHS Foundation Trust | B11: 7.9832858 | C11: 6.3677657 | E11: =IF(A11="",NA(),A11) -> Barnsley Hospital NHS Foundation Trust | F11: =IF(B11="",NA(),B11) -> 7.9832858 | G11: =IF(C11="",NA(),C11) -> 6.3677657
A12: Barts Health NHS Trust | B12: 7.4084985 | C12: 5.7934733 | E12: =IF(A12="",NA(),A12) -> Barts Health NHS Trust | F12: =IF(B12="",NA(),B12) -> 7.4084985 | G12: =IF(C12="",NA(),C12) -> 5.7934733
A13: Basildon and Thurrock University Hospitals NHS Foundation Trust | B13: 7.1491709 | C13: 6.1869216 | E13: =IF(A13="",NA(),A13) -> Basildon and Thurrock University Hospitals NHS Foundation Trust | F13: =IF(B13="",NA(),B13) -> 7.1491709 | G13: =IF(C13="",NA(),C13) -> 6.1869216
A14: Bedford Hospital NHS Trust | B14: 7.7515892 | C14: 6.3441101 | E14: =IF(A14="",NA(),A14) -> Bedford Hospital NHS Trust | F14: =IF(B14="",NA(),B14) -> 7.7515892 | G14: =IF(C14="",NA(),C14) -> 6.3441101
A15: Birmingham Women's and Children's NHS Foundation Trust | B15: 7.6546236 | C15: 6.5022666 | E15: =IF(A15="",NA(),A15) -> Birmingham Women's and Children's NHS Foundation Trust | F15: =IF(B15="",NA(),B15) -> 7.6546236 | G15: =IF(C15="",NA(),C15) -> 6.5022666
A16: Blackpool Teaching Hospitals NHS Foundation Trust | B16: 7.9247872 | C16: 4.6410658 | E16: =IF(A16="",NA(),A16) -> Blackpool Teaching Hospitals NHS Foundation Trust | F16: =IF(B16="",NA(),B16) -> 7.9247872 | G16: =IF(C16="",NA(),C16) -> 4.6410658
A17: Bolton NHS Foundation Trust | B17: 7.9203745 | C17: 5.749514 | E17: =IF(A17="",NA(),A17) -> Bolton NHS Foundation Trust | F17: =IF(B17="",NA(),B17) -> 7.9203745 | G17: =IF(C17="",NA(),C17) -> 5.749514
... A150: National | B150: 7.6279785 | C150: 6.0326221 | E150: =IF(A150="",NA(),A150) -> National | F150: =IF(B150="",NA(),B150) -> 7.6279785 | G150: =IF(C150="",NA(),C150) -> 6.0326221
E151: =IF(A151="",NA(),A151) -> #N/A | F151: =IF(B151="",NA(),B151) -> #N/A | G151: =IF(C151="",NA(),C151) -> #N/A
E152: =IF(A152="",NA(),A152) -> #N/A | F152: =IF(B152="",NA(),B152) -> #N/A | G152: =IF(C152="",NA(),C152) -> #N/A
E153: =IF(A153="",NA(),A153) -> #N/A | F153: =IF(B153="",NA(),B153) -> #N/A | G153: =IF(C153="",NA(),C153) -> #N/A
E154: =IF(ISBLANK(A154),"",A154)

Sheet Org2_Control
A5: Measure | B5: Staff Group
A6: Staff per Attendance / TTS 4 Hour | B6: Consultant
B7: Doctor (excl. Consultant)
B8: Nurse
B9: Care Provider (excl. Doctor and Nurse)
A10: Staff per Attendance / TTS 12 Hour | B10: Consultant
B11: Doctor (excl. Consultant)
B12: Nurse
B13: Care Provider (excl. Doctor and Nurse)
A14: Stability Index / TTS 4 Hour | B14: Doctor
B15: Nurse
B16: Care Provider (excl. Doctor and Nurse)
A17: Stability Index / TTS 12 Hour | B17: Doctor
B18: Nurse
B19: Care Provider (excl. Doctor and Nurse)
A20: Grand Total

Sheet Pivot2_table
A1: Measure | B1: (All) | E1: National | F1: =VLOOKUP(E1,E5:G226,2,FALSE) -> 7.6279785 | G1: =VLOOKUP(E1,E5:G211,3,FALSE) -> 6.0326221
A2: Staff Group | B2: (All)
A4: Row Labels | B4: Sum of Staff Rate | C4: Sum of Measure Rate | E4: Organisation name | F4: =B4 -> Sum of Staff Rate | G4: =C4 -> Sum of Measure Rate
A5: Aintree University Hospital NHS Foundation Trust | B5: 6.8078964 | C5: 5.9184253 | E5: =IF(A5="",NA(),A5) -> Aintree University Hospital NHS Foundation Trust | F5: =IF(B5="",NA(),B5) -> 6.8078964 | G5: =IF(C5="",NA(),C5) -> 5.9184253
A6: Airedale NHS Foundation Trust | B6: 8.4882421 | C6: 6.439245 | E6: =IF(A6="",NA(),A6) -> Airedale NHS Foundation Trust | F6: =IF(B6="",NA(),B6) -> 8.4882421 | G6: =IF(C6="",NA(),C6) -> 6.439245
A7: Alder Hey Children's NHS Foundation Trust | B7: 6.9820615 | C7: 6.640427 | E7: =IF(A7="",NA(),A7) -> Alder Hey Children's NHS Foundation Trust | F7: =IF(B7="",NA(),B7) -> 6.9820615 | G7: =IF(C7="",NA(),C7) -> 6.640427
A8: Ashford and St. Peter's Hospitals NHS Foundation Trust | B8: 7.4131313 | C8: 6.1608997 | E8: =IF(A8="",NA(),A8) -> Ashford and St. Peter's Hospitals NHS Foundation Trust | F8: =IF(B8="",NA(),B8) -> 7.4131313 | G8: =IF(C8="",NA(),C8) -> 6.1608997
A9: Barking, Havering and Redbridge University Hospitals NHS Trust | B9: 6.1752534 | C9: 5.7575514 | E9: =IF(A9="",NA(),A9) -> Barking, Havering and Redbridge University Hospitals NHS Trust | F9: =IF(B9="",NA(),B9) -> 6.1752534 | G9: =IF(C9="",NA(),C9) -> 5.7575514
A10: Barnsley Hospital NHS Foundation Trust | B10: 7.9832858 | C10: 6.3677657 | E10: =IF(A10="",NA(),A10) -> Barnsley Hospital NHS Foundation Trust | F10: =IF(B10="",NA(),B10) -> 7.9832858 | G10: =IF(C10="",NA(),C10) -> 6.3677657
A11: Barts Health NHS Trust | B11: 7.4084985 | C11: 5.7934733 | E11: =IF(A11="",NA(),A11) -> Barts Health NHS Trust | F11: =IF(B11="",NA(),B11) -> 7.4084985 | G11: =IF(C11="",NA(),C11) -> 5.7934733
A12: Basildon and Thurrock University Hospitals NHS Foundation Trust | B12: 7.1491709 | C12: 6.1869216 | E12: =IF(A12="",NA(),A12) -> Basildon and Thurrock University Hospitals NHS Foundation Trust | F12: =IF(B12="",NA(),B12) -> 7.1491709 | G12: =IF(C12="",NA(),C12) -> 6.1869216
A13: Bedford Hospital NHS Trust | B13: 7.7515892 | C13: 6.3441101 | E13: =IF(A13="",NA(),A13) -> Bedford Hospital NHS Trust | F13: =IF(B13="",NA(),B13) -> 7.7515892 | G13: =IF(C13="",NA(),C13) -> 6.3441101
A14: Birmingham Women's and Children's NHS Foundation Trust | B14: 7.6546236 | C14: 6.5022666 | E14: =IF(A14="",NA(),A14) -> Birmingham Women's and Children's NHS Foundation Trust | F14: =IF(B14="",NA(),B14) -> 7.6546236 | G14: =IF(C14="",NA(),C14) -> 6.5022666
A15: Blackpool Teaching Hospitals NHS Foundation Trust | B15: 7.9247872 | C15: 4.6410658 | E15: =IF(A15="",NA(),A15) -> Blackpool Teaching Hospitals NHS Foundation Trust | F15: =IF(B15="",NA(),B15) -> 7.9247872 | G15: =IF(C15="",NA(),C15) -> 4.6410658
A16: Bolton NHS Foundation Trust | B16: 7.9203745 | C16: 5.749514 | E16: =IF(A16="",NA(),A16) -> Bolton NHS Foundation Trust | F16: =IF(B16="",NA(),B16) -> 7.9203745 | G16: =IF(C16="",NA(),C16) -> 5.749514
... A149: York Teaching Hospital NHS Foundation Trust | B149: 7.8398783 | C149: 5.6623669 | E149: =IF(A149="",NA(),A149) -> York Teaching Hospital NHS Foundation Trust | F149: =IF(B149="",NA(),B149) -> 7.8398783 | G149: =IF(C149="",NA(),C149) -> 5.6623669
E150: =IF(A150="",NA(),A150) -> #N/A | F150: =IF(B150="",NA(),B150) -> #N/A | G150: =IF(C150="",NA(),C150) -> #N/A
E151: =IF(A151="",NA(),A151) -> #N/A | F151: =IF(B151="",NA(),B151) -> #N/A | G151: =IF(C151="",NA(),C151) -> #N/A
E152: =IF(A152="",NA(),A152) -> #N/A | F152: =IF(B152="",NA(),B152) -> #N/A | G152: =IF(C152="",NA(),C152) -> #N/A
E153: =IF(A153="",NA(),A153) -> #N/A | F153: =IF(B153="",NA(),B153) -> #N/A | G153: =IF(C153="",NA(),C153) -> #N/A

Sheet Provider_data
A1: Organisation name | B1: Organisation code | C1: Region | D1: Measure | E1: Staff Group | F1: Staff Rate | G1: Measure Rate
A2: National | B2: National | C2: National | D2: Staff per Attendance / TTS 4 Hour | E2: Consultant | F2: 0.089418076 | G2: 0.84495774
A3: National | B3: National | C3: National | D3: Staff per Attendance / TTS 4 Hour | E3: Doctor (excl. Consultant) | F3: 0.23697189 | G3: 0.84495774
A4: National | B4: National | C4: National | D4: Staff per Attendance / TTS 4 Hour | E4: Nurse | F4: 0.74818728 | G4: 0.84495774
A5: National | B5: National | C5: National | D5: Staff per Attendance / TTS 4 Hour | E5: Care Provider (excl. Doctor and Nurse) | F5: 0.39741427 | G5: 0.84495774
A6: National | B6: National | C6: National | D6: Staff per Attendance / TTS 12 Hour | E6: Consultant | F6: 0.089418076 | G6: 0.016845423
A7: National | B7: National | C7: National | D7: Staff per Attendance / TTS 12 Hour | E7: Doctor (excl. Consultant) | F7: 0.23697189 | G7: 0.016845423
A8: National | B8: National | C8: National | D8: Staff per Attendance / TTS 12 Hour | E8: Nurse | F8: 0.74818728 | G8: 0.016845423
A9: National | B9: National | C9: National | D9: Staff per Attendance / TTS 12 Hour | E9: Care Provider (excl. Doctor and Nurse) | F9: 0.39741427 | G9: 0.016845423
A10: National | B10: National | C10: National | D10: Stability Index / TTS 4 Hour | E10: Doctor | F10: 0.84366472 | G10: 0.84495774
A11: National | B11: National | C11: National | D11: Stability Index / TTS 4 Hour | E11: Nurse | F11: 0.726593 | G11: 0.84495774
A12: National | B12: National | C12: National | D12: Stability Index / TTS 4 Hour | E12: Care Provider (excl. Doctor and Nurse) | F12: 0.77174 | G12: 0.84495774
A13: National | B13: National | C13: National | D13: Stability Index / TTS 12 Hour | E13: Doctor | F13: 0.84366472 | G13: 0.016845423
... A1979: London North West University Healthcare NHS Trust | B1979: R1K | C1979: London Commissioning Region | D1979: Staff per Attendance / TTS 12 Hour | E1979: Care Provider (excl. Doctor and Nurse) | F1979: 0.78169732 | G1979: 0.078225978

Sheet Pivot_table2
C3: Values
A4: Select Provider | B4: Org code | C4: Sum of Total Unplanned | D4: Sum of 4hr % | E4: Sum of 12hr % | F4: Sum of Consultant (including Directors of Public Health) | G4: Sum of Other Doctors | H4: Sum of Nurses & health visitors | I4: Sum of Other Clinical Staff | J4: Sum of Rate Total | K4: Sum of Rate Consultant | L4: Sum of Rate Other Doctors | M4: Sum of Rate Nurses | N4: Sum of Rate other Clinical | O4: Sum of Total Clinical Staff, excl. doc and nur (SI) | P4: Sum of HCHS Doctors1 (SI) | Q4: Sum of Total Clinical Staff (SI) | R4: Sum of Nurses & health visitors (SI)
A5: Aintree University Hospital NHS Foundation Trust | B5: REM | C5: 167270 | D5: 0.82522269 | E5: 0.020266635 | F5: 15 | G5: 21.036365 | H5: 99.479993 | I5: 41.416663 | J5: 1.057769 | K5: 0.089675375 | L5: 0.12576293 | M5: 0.59472704 | N5: 0.24760365 | O5: 0.79545455 | P5: 0.83333333 | Q5: 0.75324675 | R5: 0.7173913
A6: Airedale NHS Foundation Trust | B6: RCF | C6: 57485 | D6: 0.9188484 | E6: 0.0010437505 | F6: 7.6 | G6: 17.373438 | H6: 38.573325 | I6: 28.730007 | J6: 1.6052321 | K6: 0.1322084 | L6: 0.30222558 | M6: 0.67101548 | N6: 0.49978268 | O6: 0.80555556 | P6: 1 | Q6: 0.84615385 | R6: 0.83333333
A7: Alder Hey Children's NHS Foundation Trust | B7: RBS | C7: 59960 | D7: 0.94863242 | F7: 8.2 | G7: 5.182 | H7: 43.158317 | I7: 5.71333 | J7: 1.038253 | K7: 0.13675784 | L7: 0.086424283 | M7: 0.71978515 | N7: 0.09528569 | O7: 0.77777778 | P7: 0.8 | Q7: 0.84745763 | R7: 0.875
A8: Ashford and St. Peter's Hospitals NHS Foundation Trust | B8: RTK | C8: 101150 | D8: 0.84997528 | E8: 0.030153238 | F8: 6.75 | G8: 14.25 | H8: 69.853297 | I8: 29.265932 | J8: 1.1875356 | K8: 0.066732575 | L8: 0.14087988 | M8: 0.69059118 | N8: 0.28933201 | O8: 0.81081081 | P8: 0.9 | Q8: 0.825 | R8: 0.80821918
A9: Barking, Havering and Redbridge University Hospitals NHS Trust | B9: RF4 | C9: 255250 | D9: 0.79653281 | E9: 0.025974535 | F9: 8.4 | G9: 37.45 | H9: 140.36613 | I9: 64.991595 | J9: 0.98416348 | K9: 0.032908913 | L9: 0.1467189 | M9: 0.54991629 | N9: 0.25461937 | O9: 0.68831169 | P9: 0.68181818 | Q9: 0.71590909 | R9: 0.73333333
A10: Barnsley Hospital NHS Foundation Trust | B10: RFF | C10: 85530 | D10: 0.90477026 | E10: 0.0049105577 | F10: 12.64395 | G10: 22.075 | H10: 64.59 | I10: 39.216752 | J10: 1.6196154 | K10: 0.14783059 | L10: 0.25809657 | M10: 0.75517362 | N10: 0.45851459 | O10: 0.68085106 | P10: 1 | Q10: 0.71875 | R10: 0.69117647
A11: Barts Health NHS Trust | B11: R1H | C11: 437280 | D11: 0.81487834 | E11: 0.012760703 | F11: 46.5 | G11: 121 | H11: 300.05782 | I11: 140.34467 | J11: 1.3901905 | K11: 0.10633919 | L11: 0.27671057 | M11: 0.6861915 | N11: 0.32094922 | O11: 0.79861111 | P11: 0.82692308 | Q11: 0.73852295 | R11: 0.68852459
A12: Basildon and Thurrock University Hospitals NHS Foundation Trust | B12: RDD | C12: 123715 | D12: 0.85810128 | E12: 0.025744655 | F12: 8.5 | G12: 33 | H12: 57.823318 | I12: 47.466665 | J12: 1.1865173 | K12: 0.068706301 | L12: 0.26674211 | M12: 0.46739132 | N12: 0.38367752 | O12: 0.78181818 | P12: 0.95 | Q12: 0.75539568 | R12: 0.65625
A13: Bedford Hospital NHS Trust | B13: RC1 | C13: 75935 | D13: 0.9037993 | E13: 0.00250214 | F13: 5.5 | G13: 21.329688 | H13: 49.170027 | I13: 17.666667 | J13: 1.2335074 | K13: 0.072430368 | L13: 0.28089402 | M13: 0.64752785 | N13: 0.23265513 | O13: 0.8125 | P13: 1 | Q13: 0.875 | R13: 0.82978723
A14: Birmingham Women's and Children's NHS Foundation Trust | B14: RQ3 | C14: 59560 | D14: 0.92839154 | E14: 0.00050369375 | F14: 5.5625 | G14: 18.86875 | H14: 49.63334 | I14: 16.12 | J14: 1.5141805 | K14: 0.093393217 | L14: 0.31680238 | M14: 0.83333345 | N14: 0.27065144 | O14: 0.72222222 | P14: 0.9 | Q14: 0.72289157 | R14: 0.69090909
A15: Blackpool Teaching Hospitals NHS Foundation Trust | B15: RXL | C15: 79750 | D15: 0.59015674 | E15: 0.072852665 | F15: 7.00625 | G15: 29.925 | H15: 78.943335 | I15: 46.240007 | J15: 2.0327849 | K15: 0.087852665 | L15: 0.37523511 | M15: 0.98988508 | N15: 0.57981201 | O15: 0.39130435 | P15: 0.90909091 | Q15: 0.57534247 | R15: 0.62921348
A16: Bolton NHS Foundation Trust | B16: RMC | C16: 113160 | D16: 0.81508484 | E16: 0.0062743019 | F16: 10.4 | G16: 29.357812 | H16: 98.10334 | I16: 29.526663 | J16: 1.4792136 | K16: 0.091905267 | L16: 0.25943631 | M16: 0.86694362 | N16: 0.26092844 | O16: 0.75862069 | P16: 0.88235294 | Q16: 0.82876712 | R16: 0.84
A17: Bradford Teaching Hospitals NHS Foundation Trust | B17: RAE | C17: 134270 | D17: 0.79463022 | E17: 0.0059953824 | F17: 15.0125 | G17: 35.677625 | H17: 82.499995 | I17: 52.669645 | J17: 1.3842241 | K17: 0.1118083 | L17: 0.26571554 | M17: 0.61443357 | N17: 0.39226666 | O17: 0.75806452 | P17: 0.94736842 | Q17: 0.78531073 | R17: 0.77083333
A18: Brighton and Sussex University Hospitals NHS Trust | B18: RXH | C18: 158120 | D18: 0.82854794 | E18: 0.039874779 | F18: 19.24375 | G18: 77.561972 | H18: 192.42658 | I18: 84.798285 | J18: 2.3654857 | K18: 0.12170345 | L18: 0.49052601 | M18: 1.2169655 | N18: 0.5362907 | O18: 0.76404494 | P18: 0.92592593 | Q18: 0.77477477 | R18: 0.76036866
A19: Buckinghamshire Healthcare NHS Trust | B19: RXQ | C19: 87385 | D19: 0.75081536 | E19: 0.054357155 | F19: 9.05625 | G19: 24.9 | H19: 54.678635 | I19: 29.452658 | J19: 1.351348 | K19: 0.10363621 | L19: 0.28494593 | M19: 0.62572106 | N19: 0.33704477 | O19: 0.66666667 | P19: 0.8125 | Q19: 0.648 | R19: 0.60273973
... A23: Chelsea and Westminster Hospital NHS Foundation Trust | B23: RQM | C23: 206310 | D23: 0.87055887 | E23: 0.0054287238 | F23: 17.5625 | G23: 85.003125 | H23: 166.54072 | I23: 43.883333 | J23: 1.5170844 | K23: 0.085126751 | L23: 0.4120165 | M23: 0.80723534 | N23: 0.21270579 | O23: 0.6 | P23: 0.77777778 | Q23: 0.74418605 | R23: 0.76646707
A24: Chesterfield Royal Hospital NHS Foundation Trust | B24: RFS | C24: 81280 | D24: 0.91664616 | E24: 0.00036909449 | F24: 8.0825 | G24: 21.7 | H24: 50.2225 | I24: 40.8225 | J24: 1.4865588 | K24: 0.099440207 | L24: 0.26697835 | M24: 0.61789493 | N24: 0.50224532 | O24: #N/A | P24: #N/A | Q24: #N/A | R24: #N/A
A25: City Hospitals Sunderland NHS Foundation Trust | B25: RLN | C25: 157560 | D25: 0.91212871 | E25: 0.00047600914 | F25: 10.4 | G25: 28.659375 | H25: 117.91001 | I25: 40.323332 | J25: 1.2521751 | K25: 0.066006601 | L25: 0.18189499 | M25: 0.74834987 | N25: 0.25592366 | O25: 0.97058824 | P25: 0.92307692 | Q25: 0.87150838 | R25: 0.84090909
A26: Colchester Hospital University NHS Foundation Trust | B26: RDE | C26: 91120 | D26: 0.82572432 | E26: 0.016791045 | F26: 11.25 | G26: 23.94375 | H26: 91.754993 | I26: 56.06272 | J26: 2.0084664 | K26: 0.12346356 | L26: 0.26277162 | M26: 1.0069687 | N26: 0.61526251 | O26: 0.71428571 | P26: 0.86363636 | Q26: 0.80487805 | R26: 0.82191781
A27: Countess of Chester Hospital NHS Foundation Trust | B27: RJR | C27: 82725 | D27: 0.83723179 | E27: 0.002175884 | F27: 7.85 | G27: 21.2625 | H27: 64.485 | I27: 21.4 | J27: 1.3901179 | K27: 0.094892717 | L27: 0.25702629 | M27: 0.77951043 | N27: 0.25868843 | O27: 0.8 | P27: 0.64705882 | Q27: 0.78991597 | R27: 0.80519481
A28: County Durham and Darlington NHS Foundation Trust | B28: RXP | C28: 210355 | D28: 0.9140976 | E28: 0.0051341779 | F28: 10.81 | G28: 35.1625 | H28: 106.29667 | I28: 47.935685 | J28: 0.95174753 | K28: 0.051389318 | L28: 0.1671579 | M28: 0.50532038 | N28: 0.22787994 | O28: 0.81666667 | P28: 0.86363636 | Q28: 0.85714286 | R28: 0.8411215
A29: Croydon Health Services NHS Trust | B29: RJ6 | C29: 176005 | D29: 0.89182126 | E29: 0.0097724496 | F29: 7.525 | G29: 22.770313 | H29: 78.875107 | I29: 60.541648 | J29: 0.96424572 | K29: 0.042754467 | L29: 0.1293731 | M29: 0.44814129 | N29: 0.34397686 | O29: 0.73913043 | P29: 0.88888889 | Q29: 0.72352941 | R29: 0.61956522
A30: Dartford and Gravesham NHS Trust | B30: RN7 | C30: 125700 | D30: 0.87871917 | E30: 0.021519491 | F30: 8 | G30: 26.775 | H30: 63.993712 | I30: 42.44664 | J30: 1.1234316 | K30: 0.063643596 | L30: 0.21300716 | M30: 0.50909875 | N30: 0.3376821 | O30: 0.78 | P30: 0.77777778 | Q30: 0.81506849 | R30: 0.85507246
A31: Derby Teaching Hospitals NHS Foundation Trust | B31: RTG | C31: 133240 | D31: 0.81004203 | E31: 0.0011633143 | F31: 16.3083 | G31: 53.604688 | H31: 132.49934 | I31: 88.243313 | J31: 2.1814443 | K31: 0.12239793 | L31: 0.40231678 | M31: 0.99444118 | N31: 0.66228845 | O31: 0.87628866 | P31: 0.92307692 | Q31: 0.84320557 | R31: 0.8013245
